<?xml version="1.0" ?>
<!-- =================================================================================== -->
<!-- |    This document was autogenerated by xacro from youbot_dual_arm.urdf.xacro     | -->
<!-- |    EDITING THIS FILE BY HAND IS NOT RECOMMENDED                                 | -->
<!-- =================================================================================== -->
<robot name="youbot" xmlns:controller="http://playerstage.sourceforge.net/gazebo/xmlschema/#controller" xmlns:interface="http://playerstage.sourceforge.net/gazebo/xmlschema/#interface" xmlns:sensor="http://playerstage.sourceforge.net/gazebo/xmlschema/#sensor">
  &gt;

	
  <!-- <xacro:include filename="$(find youbot_description)/urdf/youbot_gripper/gripper_urdf.urdf.xacro" /> -->
  <gazebo>
    <plugin filename="libgazebo_ros_control.so" name="gazebo_ros_controller">
      <robotSimType>gazebo_ros_control/DefaultRobotHWSim</robotSimType>
      <legacyModeNS>true</legacyModeNS>
    </plugin>
  </gazebo>
  <material name="youBot/Orange">
    <color rgba="1.0 0.4 0.0 1.0"/>
  </material>
  <material name="youBot/Grey">
    <color rgba="0.7 0.7 0.7 1.0"/>
  </material>
  <material name="youBot/DarkGrey">
    <color rgba="0.3 0.3 0.3 1.0"/>
  </material>
  <material name="youBot/White">
    <color rgba="1.0 1.0 1.0 1.0"/>
  </material>
  <material name="youBot/Black">
    <color rgba="0.0 0.0 0.0 1.0"/>
  </material>
  <material name="youBot/Red">
    <color rgba="1.0 0.0 0.0 1.0"/>
  </material>
  <material name="youBot/Green">
    <color rgba="0.0 1.0 0.0 1.0"/>
  </material>
  <material name="youBot/Blue">
    <color rgba="0.0 0.0 0.8 1.0"/>
  </material>
  <material name="youBot/LightGrey">
    <color rgba="0.82 0.82 0.82 1.0"/>
  </material>
  <!-- Now we can start using the macros xacro:included above to define the actual youbot -->
  <!-- The first use of a macro.  This one was defined in base.urdf.xacro above.
       A macro like this will expand to a set of link and joint definitions, and to additional
       Gazebo-related extensions (sensor plugins, etc).  The macro takes an argument, name, 
       that equals "base", and uses it to generate names for its component links and joints 
       (e.g., base_link).  The xacro:included origin block is also an argument to the macro.  By convention, 
       the origin block defines where the component is w.r.t its parent (in this case the parent 
       is the world frame). For more, see http://www.ros.org/wiki/xacro -->
  <link name="base_footprint">
    <inertial>
      <mass value="0.1"/>
      <origin rpy="0 0 0" xyz="0 0 -0.05"/>
      <inertia ixx="1.0" ixy="0.0" ixz="0.0" iyy="1.0" iyz="0.0" izz="1.0"/>
    </inertial>
    <visual>
      <origin rpy="0 0 0" xyz="0 0 0"/>
      <geometry>
        <box size="0.001 0.001 0.001"/>
      </geometry>
      <material name="youBot/Red"/>
    </visual>
    <collision>
      <origin rpy="0 0 0" xyz="0 0 -0.05"/>
      <geometry>
        <box size="0.001 0.001 0.001"/>
      </geometry>
    </collision>
  </link>
  <joint name="base_footprint_joint" type="fixed">
    <origin rpy="0 0 0" xyz="0 0 0"/>
    <child link="base_link"/>
    <parent link="base_footprint"/>
  </joint>
  <link name="base_link">
    <inertial>
      <mass value="22.0"/>
      <origin xyz="0 0 0"/>
      <inertia ixx="5.652232699207" ixy="-0.009719934438" ixz="1.293988226423" iyy="5.669473158652" iyz="-0.007379583694" izz="3.683196351726"/>
    </inertial>
    <visual>
      <origin rpy="0 0 0" xyz="0 0 0"/>
      <geometry>
        <mesh filename="package://youbot_description/meshes/youbot_base/base.dae"/>
      </geometry>
      <material name="youBot/DarkGrey"/>
    </visual>
    <collision>
      <origin rpy="0 0 0" xyz="0 0 0"/>
      <geometry>
        <!--<box size="${base_size_x} ${base_size_y} ${base_size_z}" />-->
        <mesh filename="package://youbot_description/meshes/youbot_base/base_convex.dae"/>
      </geometry>
    </collision>
  </link>
  <!-- front left wheel -->
  <joint name="caster_joint_fl" type="continuous">
    <origin rpy="0 0 0" xyz="0.228 0.158 -0.034"/>
    <axis xyz="0 0 1"/>
    <limit effort="30" velocity="10"/>
    <dynamics damping="1.0" friction="1.0"/>
    <safety_controller k_velocity="10.0"/>
    <parent link="base_link"/>
    <child link="caster_link_fl"/>
  </joint>
  <link name="caster_link_fl">
    <inertial>
      <mass value="0.1"/>
      <origin xyz="0 0 0"/>
      <inertia ixx="0.012411765597" ixy="-0.000711733678" ixz="0.00050272983" iyy="0.015218160428" iyz="-0.000004273467" izz="0.011763977943"/>
    </inertial>
  </link>
  <joint name="wheel_joint_fl" type="continuous">
    <axis xyz="0 1 0"/>
    <limit effort="30" velocity="10"/>
    <origin rpy="0 0 0" xyz="0.0 0.0 0.0"/>
    <parent link="caster_link_fl"/>
    <dynamics damping="1.0" friction="1.0"/>
    <safety_controller k_velocity="10.0"/>
    <child link="wheel_link_fl"/>
  </joint>
  <link name="wheel_link_fl">
    <inertial>
      <mass value="1.4"/>
      <origin xyz="0 0 0"/>
      <inertia ixx="0.012411765597" ixy="-0.000711733678" ixz="0.00050272983" iyy="0.015218160428" iyz="-0.000004273467" izz="0.011763977943"/>
    </inertial>
    <visual>
      <origin rpy="0 0 0" xyz="0 0 0"/>
      <!--<mesh filename="package://youbot_description/meshes/youbot_base/youbot_wheel.stl" />-->
      <geometry>
        <sphere radius="0.0475"/>
      </geometry>
      <material name="youBot/Orange"/>
    </visual>
    <collision>
      <origin rpy="1.5707963267948966 0 0" xyz="0 0 0"/>
      <geometry>
        <cylinder length="0.0475" radius="0.0475"/>
      </geometry>
    </collision>
  </link>
  <!-- front right wheel -->
  <joint name="caster_joint_fr" type="continuous">
    <origin rpy="0 0 0" xyz="0.228 -0.158 -0.034"/>
    <axis xyz="0 0 1"/>
    <limit effort="30" velocity="10"/>
    <dynamics damping="1.0" friction="1.0"/>
    <safety_controller k_velocity="10.0"/>
    <parent link="base_link"/>
    <child link="caster_link_fr"/>
  </joint>
  <link name="caster_link_fr">
    <inertial>
      <mass value="0.1"/>
      <origin xyz="0 0 0"/>
      <inertia ixx="0.012411765597" ixy="-0.000711733678" ixz="0.00050272983" iyy="0.015218160428" iyz="-0.000004273467" izz="0.011763977943"/>
    </inertial>
  </link>
  <joint name="wheel_joint_fr" type="continuous">
    <axis xyz="0 1 0"/>
    <limit effort="30" velocity="10"/>
    <dynamics damping="1.0" friction="1.0"/>
    <safety_controller k_velocity="10.0"/>
    <origin rpy="0 0 0" xyz="0.0 0.0 0.0"/>
    <parent link="caster_link_fr"/>
    <child link="wheel_link_fr"/>
  </joint>
  <link name="wheel_link_fr">
    <inertial>
      <mass value="1.4"/>
      <origin xyz="0 0 0"/>
      <inertia ixx="0.012411765597" ixy="-0.000711733678" ixz="0.00050272983" iyy="0.015218160428" iyz="-0.000004273467" izz="0.011763977943"/>
    </inertial>
    <visual>
      <origin rpy="0 0 0" xyz="0 0 0"/>
      <geometry>
        <!--<mesh filename="package://youbot_description/meshes/youbot_base/youbot_wheel.stl" />-->
        <sphere radius="0.0475"/>
      </geometry>
      <material name="youBot/Orange"/>
    </visual>
    <collision>
      <origin rpy="1.5707963267948966 0 0" xyz="0 0 0"/>
      <geometry>
        <cylinder length="0.0475" radius="0.0475"/>
      </geometry>
    </collision>
  </link>
  <!-- back left wheel -->
  <joint name="caster_joint_bl" type="continuous">
    <origin rpy="0 0 0" xyz="-0.228 0.158 -0.034"/>
    <axis xyz="0 0 1"/>
    <limit effort="30" velocity="10"/>
    <dynamics damping="1.0" friction="1.0"/>
    <safety_controller k_velocity="10.0"/>
    <parent link="base_link"/>
    <child link="caster_link_bl"/>
  </joint>
  <link name="caster_link_bl">
    <inertial>
      <mass value="0.1"/>
      <origin xyz="0 0 0"/>
      <inertia ixx="0.012411765597" ixy="-0.000711733678" ixz="0.00050272983" iyy="0.015218160428" iyz="-0.000004273467" izz="0.011763977943"/>
    </inertial>
  </link>
  <joint name="wheel_joint_bl" type="continuous">
    <axis xyz="0 1 0"/>
    <limit effort="10" velocity="10"/>
    <limit effort="30" velocity="10"/>
    <dynamics damping="1.0" friction="1.0"/>
    <safety_controller k_velocity="10.0"/>
    <origin rpy="0 0 0" xyz="0.0 0.0 0.0"/>
    <parent link="caster_link_bl"/>
    <child link="wheel_link_bl"/>
  </joint>
  <link name="wheel_link_bl">
    <inertial>
      <mass value="1.4"/>
      <origin xyz="0 0 0"/>
      <inertia ixx="0.012411765597" ixy="-0.000711733678" ixz="0.00050272983" iyy="0.015218160428" iyz="-0.000004273467" izz="0.011763977943"/>
    </inertial>
    <visual>
      <origin rpy="0 0 0" xyz="0 0 0"/>
      <geometry>
        <!--<mesh filename="package://youbot_description/meshes/youbot_base/youbot_wheel.stl" />-->
        <sphere radius="0.0475"/>
      </geometry>
      <material name="youBot/Orange"/>
    </visual>
    <collision>
      <origin rpy="1.5707963267948966 0 0" xyz="0 0 0"/>
      <geometry>
        <cylinder length="0.0475" radius="0.0475"/>
      </geometry>
    </collision>
  </link>
  <!-- back right wheel -->
  <joint name="caster_joint_br" type="continuous">
    <origin rpy="0 0 0" xyz="-0.228 -0.158 -0.034"/>
    <axis xyz="0 0 1"/>
    <limit effort="30" velocity="10"/>
    <dynamics damping="1.0" friction="1.0"/>
    <safety_controller k_velocity="10.0"/>
    <parent link="base_link"/>
    <child link="caster_link_br"/>
  </joint>
  <link name="caster_link_br">
    <inertial>
      <mass value="0.1"/>
      <origin xyz="0 0 0"/>
      <inertia ixx="0.012411765597" ixy="-0.000711733678" ixz="0.00050272983" iyy="0.015218160428" iyz="-0.000004273467" izz="0.011763977943"/>
    </inertial>
  </link>
  <joint name="wheel_joint_br" type="continuous">
    <axis xyz="0 1 0"/>
    <limit effort="30" velocity="10"/>
    <dynamics damping="1.0" friction="1.0"/>
    <safety_controller k_velocity="10.0"/>
    <origin rpy="0 0 0" xyz="0.0 0.0 0.0"/>
    <parent link="caster_link_br"/>
    <child link="wheel_link_br"/>
  </joint>
  <link name="wheel_link_br">
    <inertial>
      <mass value="1.4"/>
      <origin xyz="0 0 0"/>
      <inertia ixx="0.012411765597" ixy="-0.000711733678" ixz="0.00050272983" iyy="0.015218160428" iyz="-0.000004273467" izz="0.011763977943"/>
    </inertial>
    <visual>
      <origin rpy="0 0 0" xyz="0 0 0"/>
      <geometry>
        <!--<mesh filename="package://youbot_description/meshes/youbot_base/youbot_wheel.stl" />-->
        <sphere radius="0.0475"/>
      </geometry>
      <material name="youBot/Orange"/>
    </visual>
    <collision>
      <origin rpy="1.5707963267948966 0 0" xyz="0 0 0"/>
      <geometry>
        <cylinder length="0.0475" radius="0.0475"/>
      </geometry>
    </collision>
  </link>
  <gazebo reference="youbot_base">
    </gazebo>
  <!-- front left wheel -->
  <gazebo reference="wheel_link_fl">
    <kp>1000000</kp>
    <kd>100</kd>
  </gazebo>
  <gazebo reference="caster_link_fl">
    </gazebo>
  <!-- front right wheel -->
  <gazebo reference="wheel_link_fr">
    <kp>1000000</kp>
    <kd>100</kd>
  </gazebo>
  <gazebo reference="caster_link_fr">   
    </gazebo>
  <!-- back left wheel -->
  <gazebo reference="wheel_link_bl">
    <kp>1000000</kp>
    <kd>100</kd>
  </gazebo>
  <gazebo reference="caster_link_bl">
    </gazebo>
  <!-- back right wheel -->
  <gazebo reference="wheel_link_br">
    <kp>1000000</kp>
    <kd>100</kd>
  </gazebo>
  <gazebo reference="caster_link_br">
    </gazebo>
  <!-- front left wheel -->
  <transmission name="wheel_trans_fl">
    <type>transmission_interface/SimpleTransmission</type>
    <actuator name="wheel_motor_fl">
      <hardwareInterface>hardware_interface/VelocityJointInterface</hardwareInterface>
      <mechanicalReduction>79.23809523809524</mechanicalReduction>
    </actuator>
    <joint name="wheel_joint_fl">
      <hardwareInterface>hardware_interface/VelocityJointInterface</hardwareInterface>
    </joint>
  </transmission>
  <transmission name="caster_trans_fl">
    <type>transmission_interface/SimpleTransmission</type>
    <actuator name="caster_motor_fl">
      <hardwareInterface>hardware_interface/VelocityJointInterface</hardwareInterface>
      <mechanicalReduction>79.23809523809524</mechanicalReduction>
    </actuator>
    <joint name="caster_joint_fl">
      <hardwareInterface>hardware_interface/VelocityJointInterface</hardwareInterface>
    </joint>
  </transmission>
  <!-- front right wheel -->
  <transmission name="wheel_trans_fr">
    <type>transmission_interface/SimpleTransmission</type>
    <actuator name="wheel_motor_fr">
      <hardwareInterface>hardware_interface/VelocityJointInterface</hardwareInterface>
      <mechanicalReduction>79.23809523809524</mechanicalReduction>
    </actuator>
    <joint name="wheel_joint_fr">
      <hardwareInterface>hardware_interface/VelocityJointInterface</hardwareInterface>
    </joint>
  </transmission>
  <transmission name="caster_trans_fr">
    <type>transmission_interface/SimpleTransmission</type>
    <actuator name="caster_motor_fr">
      <hardwareInterface>hardware_interface/VelocityJointInterface</hardwareInterface>
      <mechanicalReduction>79.23809523809524</mechanicalReduction>
    </actuator>
    <joint name="caster_joint_fr">
      <hardwareInterface>hardware_interface/VelocityJointInterface</hardwareInterface>
    </joint>
  </transmission>
  <!-- back left wheel -->
  <transmission name="wheel_trans_bl">
    <type>transmission_interface/SimpleTransmission</type>
    <actuator name="wheel_motor_bl">
      <hardwareInterface>hardware_interface/VelocityJointInterface</hardwareInterface>
      <mechanicalReduction>79.23809523809524</mechanicalReduction>
    </actuator>
    <joint name="wheel_joint_bl">
      <hardwareInterface>hardware_interface/VelocityJointInterface</hardwareInterface>
    </joint>
  </transmission>
  <transmission name="caster_trans_bl">
    <type>transmission_interface/SimpleTransmission</type>
    <actuator name="caster_motor_bl">
      <hardwareInterface>hardware_interface/VelocityJointInterface</hardwareInterface>
      <mechanicalReduction>79.23809523809524</mechanicalReduction>
    </actuator>
    <joint name="caster_joint_bl">
      <hardwareInterface>hardware_interface/VelocityJointInterface</hardwareInterface>
    </joint>
  </transmission>
  <!-- back right wheel -->
  <transmission name="wheel_trans_br">
    <type>transmission_interface/SimpleTransmission</type>
    <actuator name="wheel_motor_br">
      <hardwareInterface>hardware_interface/VelocityJointInterface</hardwareInterface>
      <mechanicalReduction>79.23809523809524</mechanicalReduction>
    </actuator>
    <joint name="wheel_joint_br">
      <hardwareInterface>hardware_interface/VelocityJointInterface</hardwareInterface>
    </joint>
  </transmission>
  <transmission name="caster_trans_br">
    <type>transmission_interface/SimpleTransmission</type>
    <actuator name="caster_motor_br">
      <hardwareInterface>hardware_interface/VelocityJointInterface</hardwareInterface>
      <mechanicalReduction>79.23809523809524</mechanicalReduction>
    </actuator>
    <joint name="caster_joint_br">
      <hardwareInterface>hardware_interface/VelocityJointInterface</hardwareInterface>
    </joint>
  </transmission>
  <!-- <xacro:youbot_plate name="plate" parent="base_link">
    <origin xyz="0 0 0.02" rpy="0 0 0" />
  </xacro:youbot_plate> -->
  <!-- joint between base_link and arm_0_link -->
  <joint name="arm_joint_0" type="fixed">
    <origin rpy="0 0 0" xyz="0.123 0 0.046"/>
    <parent link="base_link"/>
    <child link="arm_link_0"/>
  </joint>
  <link name="arm_link_0">
    <inertial>
      <!--<origin xyz="0.023 0 0.006" rpy="0 0 0"/>-->
      <origin rpy="0 0 0" xyz="0 0 0"/>
      <mass value="0.845"/>
      <inertia ixx="0.01" ixy="0" ixz="0" iyy="0.01" iyz="0" izz="0.01"/>
    </inertial>
    <visual>
      <origin rpy="0 0 0" xyz="0 0 0"/>
      <geometry>
        <mesh filename="package://youbot_description/meshes/youbot_arm/arm0.dae"/>
      </geometry>
      <material name="youBot/DarkGrey"/>
    </visual>
    <collision>
      <!--<origin xyz="0.023 0 0.006" rpy="0 0 0"/>-->
      <origin rpy="0 0 0" xyz="0 0 0"/>
      <geometry>
        <mesh filename="package://youbot_description/meshes/youbot_arm/arm0_convex.dae"/>
        <!--<cylinder length="0.078" radius="0.093"/>-->
      </geometry>
    </collision>
  </link>
  <!-- joint between arm_0_link and arm_1_link -->
  <joint name="arm_joint_1" type="revolute">
    <origin rpy="0 0 2.9670597283903604" xyz="0.024 0 0.096"/>
    <parent link="arm_link_0"/>
    <child link="arm_link_1"/>
    <axis xyz="0 0 -1"/>
    <!--<calibration rising="${arm_1_ref}" falling="${arm_1_ref}"/>-->
    <dynamics damping="1" friction="0.5"/>
    <!-- damping - N*s/m, N*s*m/rad -->
    <!-- friction - N, N*m -->
    <limit effort="9.5" lower="0" upper="5.899212871740834" velocity="1.5707963267948966"/>
    <!--effort - N, N*m-->
    <!--velocity - m/s, rad/s-->
    <!--safety_controller k_position="20" k_velocity="${9.5/M_PI / 2.0}" soft_lower_limit="${threshold}" soft_upper_limit="${joint_1_limit_soft}" /-->
    <!--k_position N/m, N/rad-->
    <!--k_velocity N*s/m, N*s*m/rad-->
    <!--for details: http://www.ros.org/wiki/pr2_controller_manager/safety_limits-->
  </joint>
  <link name="arm_link_1">
    <inertial>
      <mass value="2.412"/>
      <origin rpy="0 0 0" xyz="0.01489 0.00213 0.00213"/>
      <inertia ixx="0.003863" ixy="-0.000979" ixz="0.000000" iyy="0.006196" iyz="0.000000" izz="0.006369"/>
    </inertial>
    <visual>
      <origin rpy="0 0 0" xyz="0 0 0"/>
      <geometry>
        <mesh filename="package://youbot_description/meshes/youbot_arm/arm1.dae"/>
      </geometry>
      <material name="youBot/Orange"/>
    </visual>
    <collision>
      <!--<origin xyz="0 0 -0.003" rpy="0 0 0" />-->
      <origin rpy="0 0 0" xyz="0 0 0"/>
      <geometry>
        <mesh filename="package://youbot_description/meshes/youbot_arm/arm1_convex.dae"/>
        <!--<cylinder length="0.102" radius="0.080"/>-->
      </geometry>
    </collision>
  </link>
  <!-- joint between arm_1_link and arm_2_link -->
  <joint name="arm_joint_2" type="revolute">
    <origin rpy="0 -1.1344640137963142 0" xyz="0.033 0 0.019"/>
    <parent link="arm_link_1"/>
    <child link="arm_link_2"/>
    <axis xyz="0 1 0"/>
    <!--<calibration rising="${arm_2_ref}" falling="${arm_2_ref}"/>-->
    <dynamics damping="1" friction="0.5"/>
    <limit effort="9.5" lower="0" upper="2.705260340591211" velocity="1.5707963267948966"/>
    <!--safety_controller k_position="20" k_velocity="${2*9.5/M_PI}" soft_lower_limit="${threshold}" soft_upper_limit="${joint_2_limit_soft}" /-->
  </joint>
  <link name="arm_link_2">
    <inertial>
      <mass value="1.155"/>
      <origin rpy="0 0 0" xyz="0.10453 0.0017 -0.00297"/>
      <inertia ixx="0.000823" ixy="0.000000" ixz="-0.000000" iyy="0.004447" iyz="0.000000" izz="0.004439"/>
    </inertial>
    <visual>
      <origin rpy="0 0 0" xyz="0 -0.032 0.078"/>
      <geometry>
        <mesh filename="package://youbot_description/meshes/youbot_arm/arm2.dae"/>
      </geometry>
    </visual>
    <collision>
      <!--<origin xyz="0.001 -0.041 0.074" rpy="0 0 0" />-->
      <origin rpy="0 0 0" xyz="0 -0.032 0.078"/>
      <geometry>
        <mesh filename="package://youbot_description/meshes/youbot_arm/arm2_convex.dae"/>
        <!--<box size="0.074 0.082 0.222"/>-->
      </geometry>
    </collision>
  </link>
  <!-- joint between arm_2_link and arm_3_link -->
  <!--<joint name="${name}_joint_3" type="revolute">
			<origin xyz="0.000 0.000 0.155" rpy="0 ${146 * M_PI / 180} 0"/>
			<parent link="${name}_link_2"/>
			<child link="${name}_link_3"/>
			<axis xyz="0 1 0"/>
			<dynamics damping="1" friction="1" />
			<limit effort="${6}" velocity="${M_PI / 2.0}" lower="-${joint_3_limit}" upper="0"/>
      <safety_controller k_position="20" k_velocity="50" soft_lower_limit="-${joint_3_limit_soft}" soft_upper_limit="${threshold}" />
		</joint>-->
  <joint name="arm_joint_3" type="revolute">
    <origin rpy="0 2.548180707911721 0" xyz="0.000 0.000 0.155"/>
    <parent link="arm_link_2"/>
    <child link="arm_link_3"/>
    <axis xyz="0 1 0"/>
    <dynamics damping="1" friction="0.5"/>
    <limit effort="6.0" lower="-5.183627878423159" upper="0" velocity="1.5707963267948966"/>
    <!--safety_controller k_position="20" k_velocity="50" soft_lower_limit="-${joint_3_limit_soft}" soft_upper_limit="-${threshold}" /-->
  </joint>
  <link name="arm_link_3">
    <inertial>
      <mass value="0.934"/>
      <origin rpy="0 0 0" xyz="0.0001 0.09670000000000001 0.021070000000000002"/>
      <inertia ixx="0.002459" ixy="0.000000" ixz="0.000000" iyy="0.002571" iyz="-0.000000" izz="0.000535"/>
    </inertial>
    <visual>
      <origin rpy="0 0 0" xyz="0.000 0.028 0.079"/>
      <geometry>
        <mesh filename="package://youbot_description/meshes/youbot_arm/arm3.dae"/>
      </geometry>
      <material name="youBot/Orange"/>
    </visual>
    <collision>
      <!--<origin xyz="0.000 0.025 0.067" rpy="0 0 0" />-->
      <origin rpy="0 0 0" xyz="0.000 0.028 0.079"/>
      <geometry>
        <mesh filename="package://youbot_description/meshes/youbot_arm/arm3_convex.dae"/>
        <!--<box size="0.064 0.054 0.192"/>-->
      </geometry>
    </collision>
  </link>
  <!-- joint between arm_3_link and arm_4_link -->
  <joint name="arm_joint_4" type="revolute">
    <origin rpy="0 -1.7889624832941877 0" xyz="0.000 0.000 0.135"/>
    <parent link="arm_link_3"/>
    <child link="arm_link_4"/>
    <axis xyz="0 1 0"/>
    <!--<calibration rising="${arm_4_ref}" falling="${arm_4_ref}"/>-->
    <dynamics damping="1" friction="0.5"/>
    <limit effort="2.0" lower="0" upper="3.5779249665883754" velocity="1.5707963267948966"/>
    <!--safety_controller k_position="20" k_velocity="100" soft_lower_limit="0" soft_upper_limit="${joint_4_limit_soft}" /-->
  </joint>
  <link name="arm_link_4">
    <inertial>
      <mass value="0.877"/>
      <origin rpy="0 0 0" xyz="0.00011 0.05103 -0.023190000000000002"/>
      <inertia ixx="0.000869" ixy="0.000000" ixz="-0.000000" iyy="0.001173" iyz="-0.000231" izz="0.001091"/>
    </inertial>
    <visual>
      <origin rpy="0 0 0" xyz="0 -0.010 0.029"/>
      <geometry>
        <mesh filename="package://youbot_description/meshes/youbot_arm/arm4.dae"/>
      </geometry>
      <material name="youBot/Orange"/>
    </visual>
    <collision>
      <!--<origin xyz="0 0 0.026" rpy="0 0 0" />-->
      <origin rpy="0 0 0" xyz="0 -0.010 0.029"/>
      <geometry>
        <mesh filename="package://youbot_description/meshes/youbot_arm/arm4_convex.dae"/>
        <!--<box size="0.058 0.100 0.118"/>-->
      </geometry>
    </collision>
  </link>
  <!-- joint between arm_4_link and arm_5_link -->
  <joint name="arm_joint_5" type="revolute">
    <origin rpy="0 0 2.9234264970905017" xyz="-0.002 0 0.130"/>
    <parent link="arm_link_4"/>
    <child link="arm_link_5"/>
    <axis xyz="0 0 -1"/>
    <!--<calibration rising="${arm_5_ref}" falling="${arm_5_ref}"/>-->
    <dynamics damping="0.5" friction="0.5"/>
    <limit effort="1.0" lower="0" upper="5.8468529941810035" velocity="1.5707963267948966"/>
    <!--safety_controller k_position="20" k_velocity="100" soft_lower_limit="0" soft_upper_limit="${joint_5_limit_soft}" /-->
  </joint>
  <link name="arm_link_5">
    <inertial>
      <mass value="0.251"/>
      <origin rpy="0 0 0" xyz="0.0 0.00115 -0.016829999999999998"/>
      <inertia ixx="0.000280" ixy="0.000000" ixz="0.000000" iyy="0.000339" iyz="0.000000" izz="0.000119"/>
    </inertial>
    <visual>
      <origin rpy="0 0 0" xyz="0.003 0 -0.034"/>
      <geometry>
        <mesh filename="package://youbot_description/meshes/youbot_arm/arm5.dae"/>
      </geometry>
      <material name="youBot/DarkGrey"/>
    </visual>
    <collision>
      <origin rpy="0 0 0" xyz="0.003 0 -0.034"/>
      <geometry>
        <mesh filename="package://youbot_description/meshes/youbot_arm/arm5_convex.dae"/>
        <!--<box size="0.054 0.096 0.030"/>-->
      </geometry>
    </collision>
  </link>
  <gazebo reference="arm_link_0">
    <turnGravityOff>false</turnGravityOff>
  </gazebo>
  <gazebo reference="arm_link_1">
    <turnGravityOff>false</turnGravityOff>
  </gazebo>
  <gazebo reference="arm_link_2">
    <turnGravityOff>false</turnGravityOff>
  </gazebo>
  <gazebo reference="arm_link_3">
    <turnGravityOff>false</turnGravityOff>
  </gazebo>
  <gazebo reference="arm_link_4">
    <turnGravityOff>false</turnGravityOff>
  </gazebo>
  <gazebo reference="arm_link_5">
    <turnGravityOff>false</turnGravityOff>
  </gazebo>
  <transmission name="arm_trans_1">
    <type>transmission_interface/SimpleTransmission</type>
    <actuator name="arm_motor_1">
      <hardwareInterface>hardware_interface/EffortJointInterface</hardwareInterface>
      <mechanicalReduction>1</mechanicalReduction>
    </actuator>
    <joint name="arm_joint_1">
      <hardwareInterface>hardware_interface/EffortJointInterface</hardwareInterface>
    </joint>
  </transmission>
  <transmission name="arm_trans_2">
    <type>transmission_interface/SimpleTransmission</type>
    <actuator name="arm_motor_2">
      <hardwareInterface>hardware_interface/EffortJointInterface</hardwareInterface>
      <mechanicalReduction>1</mechanicalReduction>
    </actuator>
    <joint name="arm_joint_2">
      <hardwareInterface>hardware_interface/EffortJointInterface</hardwareInterface>
    </joint>
  </transmission>
  <transmission name="arm_trans_3">
    <type>transmission_interface/SimpleTransmission</type>
    <actuator name="arm_motor_3">
      <hardwareInterface>hardware_interface/EffortJointInterface</hardwareInterface>
      <mechanicalReduction>1</mechanicalReduction>
    </actuator>
    <joint name="arm_joint_3">
      <hardwareInterface>hardware_interface/EffortJointInterface</hardwareInterface>
    </joint>
  </transmission>
  <transmission name="arm_trans_4">
    <type>transmission_interface/SimpleTransmission</type>
    <actuator name="arm_motor_4">
      <hardwareInterface>hardware_interface/EffortJointInterface</hardwareInterface>
      <mechanicalReduction>1</mechanicalReduction>
    </actuator>
    <joint name="arm_joint_4">
      <hardwareInterface>hardware_interface/EffortJointInterface</hardwareInterface>
    </joint>
  </transmission>
  <transmission name="arm_trans_5">
    <type>transmission_interface/SimpleTransmission</type>
    <actuator name="arm_motor_5">
      <hardwareInterface>hardware_interface/EffortJointInterface</hardwareInterface>
      <mechanicalReduction>1</mechanicalReduction>
    </actuator>
    <joint name="arm_joint_5">
      <hardwareInterface>hardware_interface/EffortJointInterface</hardwareInterface>
    </joint>
  </transmission>
  <joint name="gripper_holder_joint" type="fixed">
    <origin rpy="0 0 -1.5708" xyz="-0.00031 -0.01549 -0.017"/>
    <parent link="arm_link_5"/>
    <child link="gripper_base_holder_link"/>
  </joint>
  <link name="gripper_base_holder_link">
    <inertial>
      <origin rpy="0 0 0" xyz="-0.0154913714783607 0.0138130469937227 -0.00019122623023348"/>
      <mass value="0.325166075012768"/>
      <inertia ixx="0.000176422818214742" ixy="-1.14630099641922E-09" ixz="-9.58997413681059E-09" iyy="0.000240392345030757" iyz="-7.04160665163785E-07" izz="0.000314342023674162"/>
    </inertial>
    <visual>
      <origin rpy="0 0 0" xyz="0 0 0"/>
      <geometry>
        <mesh filename="package://youbot_description/meshes/youbot_gripper/base_holder_link.STL"/>
      </geometry>
      <material name="">
        <color rgba="1.0 0.4 0.0 1.0"/>
      </material>
    </visual>
    <collision>
      <origin rpy="0 0 0" xyz="0 0 0"/>
      <geometry>
        <mesh filename="package://youbot_description/meshes/youbot_gripper/base_holder_link.STL"/>
      </geometry>
    </collision>
  </link>
  <link name="gripper_servo_left_link">
    <inertial>
      <origin rpy="0 0 0" xyz="0.020150145575314 0.0101 0.0198454858796802"/>
      <mass value="0.0338275279922958"/>
      <inertia ixx="5.70756586656377E-06" ixy="5.80148509440568E-23" ixz="8.86766496554433E-08" iyy="9.51111668532985E-06" iyz="-6.32864720294365E-23" izz="6.07620941885605E-06"/>
    </inertial>
    <visual>
      <origin rpy="0 0 0" xyz="0 0 0"/>
      <geometry>
        <mesh filename="package://youbot_description/meshes/youbot_gripper/servo_left_link.STL"/>
      </geometry>
      <material name="">
        <color rgba="0.0 0.0 0.0 1.0"/>
      </material>
    </visual>
  </link>
  <joint name="gripper_servo_left_joint" type="fixed">
    <origin rpy="1.5707963267949 1.5707963267949 0" xyz="-0.0397908009150208 0.0238 0.0564"/>
    <parent link="gripper_base_holder_link"/>
    <child link="gripper_servo_left_link"/>
    <axis xyz="0 0 0"/>
  </joint>
  <link name="gripper_left_finger_fastener_link">
    <inertial>
      <origin rpy="0 0 0" xyz="0.00226372174067158 0.0199992839781028 -0.0234471080962139"/>
      <mass value="0.0"/>
      <inertia ixx="1" ixy="0" ixz="0" iyy="1" iyz="0" izz="0"/>
    </inertial>
    <visual>
      <origin rpy="0 0 0" xyz="0 0 0"/>
      <geometry>
        <mesh filename="package://youbot_description/meshes/youbot_gripper/left_finger_fastener_link.STL"/>
      </geometry>
      <material name="">
        <color rgba="1.0 0.4 0.0 1.0"/>
      </material>
    </visual>
    <collision>
      <origin rpy="0 0 0" xyz="0 0 0"/>
      <geometry>
        <mesh filename="package://youbot_description/meshes/youbot_gripper/left_finger_fastener_link.STL"/>
      </geometry>
    </collision>
  </link>
  <joint name="gripper_left_finger_fastener_joint" type="revolute">
    <origin rpy="3.14159265358979 0 -1.58659399800857" xyz="0.0102000000000002 0.0101 0"/>
    <parent link="gripper_servo_left_link"/>
    <child link="gripper_left_finger_fastener_link"/>
    <axis xyz="0 0 1"/>
    <limit effort="1000.0" lower="-1.65" upper="0.05" velocity="0.5"/>
  </joint>
  <link name="gripper_left_finger_link">
    <inertial>
      <origin rpy="0 0 0" xyz="0.0169959009662644 -0.0172451544705946 0.018"/>
      <mass value="0.0684728752073224"/>
      <inertia ixx="1.92584731118216E-05" ixy="3.85525749503484E-06" ixz="2.91277822181814E-20" iyy="8.23467568536262E-06" iyz="-1.04607349996278E-20" izz="2.03605576297548E-05"/>
    </inertial>
    <visual>
      <origin rpy="0 0 0" xyz="0 0 0"/>
      <geometry>
        <mesh filename="package://youbot_description/meshes/youbot_gripper/left_finger_link.STL"/>
      </geometry>
      <material name="">
        <color rgba="1.0 1.0 1.0 1.0"/>
      </material>
    </visual>
    <collision>
      <origin rpy="0 0 0" xyz="0 0 0"/>
      <geometry>
        <mesh filename="package://youbot_description/meshes/youbot_gripper/left_finger_link.STL"/>
      </geometry>
    </collision>
  </link>
  <joint name="gripper_left_finger_joint" type="fixed">
    <origin rpy="0 0 -3.14159265358979" xyz="0.0154362314517575 0.0263000000000004 -0.0399"/>
    <parent link="gripper_left_finger_fastener_link"/>
    <child link="gripper_left_finger_link"/>
    <axis xyz="0 0 0"/>
  </joint>
  <link name="gripper_servo_right_link">
    <inertial>
      <origin rpy="0 0 0" xyz="0.020150145575314 0.0101 0.0198454858796802"/>
      <mass value="0.0338275279922958"/>
      <inertia ixx="5.70756586656377E-06" ixy="7.85985176003018E-23" ixz="8.86766496554432E-08" iyy="9.51111668532985E-06" iyz="-1.83701156015215E-22" izz="6.07620941885605E-06"/>
    </inertial>
    <visual>
      <origin rpy="0 0 0" xyz="0 0 0"/>
      <geometry>
        <mesh filename="package://youbot_description/meshes/youbot_gripper/servo_right_link.STL"/>
      </geometry>
      <material name="">
        <color rgba="0.0 0.0 0.0 1.0"/>
      </material>
    </visual>
  </link>
  <joint name="gripper_servo_right_joint" type="fixed">
    <origin rpy="1.5707963267949 1.5707963267949 0" xyz="-0.0113908009150208 0.0238 0.0564"/>
    <parent link="gripper_base_holder_link"/>
    <child link="gripper_servo_right_link"/>
    <axis xyz="0 0 0"/>
  </joint>
  <link name="gripper_right_finger_fastener_link">
    <inertial>
      <origin rpy="0 0 0" xyz="-0.00226372174067153 0.0199992839781026 -0.0234471080962139"/>
      <mass value="0.0"/>
      <inertia ixx="1" ixy="0" ixz="0" iyy="1" iyz="0" izz="0"/>
    </inertial>
    <visual>
      <origin rpy="0 0 0" xyz="0 0 0"/>
      <geometry>
        <mesh filename="package://youbot_description/meshes/youbot_gripper/right_finger_fastener_link.STL"/>
      </geometry>
      <material name="">
        <color rgba="1.0 0.4 0.0 1.0"/>
      </material>
    </visual>
    <collision>
      <origin rpy="0 0 0" xyz="0 0 0"/>
      <geometry>
        <mesh filename="package://youbot_description/meshes/youbot_gripper/right_finger_fastener_link.STL"/>
      </geometry>
    </collision>
  </link>
  <joint name="gripper_right_finger_fastener_joint" type="revolute">
    <origin rpy="3.14159265358979 0 -1.58829722752844" xyz="0.0102000000000001 0.0101 0"/>
    <parent link="gripper_servo_right_link"/>
    <child link="gripper_right_finger_fastener_link"/>
    <axis xyz="0 0 1"/>
    <limit effort="1000.0" lower="-0.02" upper="1.65" velocity="0.5"/>
  </joint>
  <link name="gripper_right_finger_link">
    <inertial>
      <origin rpy="0 0 0" xyz="0.0169959009662644 -0.0172451544705946 0.018"/>
      <mass value="0.0684728752073222"/>
      <inertia ixx="1.92584731118215E-05" ixy="3.85525749503483E-06" ixz="2.57564826261444E-20" iyy="8.23467568536258E-06" iyz="-2.12579001275468E-21" izz="2.03605576297547E-05"/>
    </inertial>
    <visual>
      <origin rpy="0 0 0" xyz="0 0 0"/>
      <geometry>
        <mesh filename="package://youbot_description/meshes/youbot_gripper/right_finger_link.STL"/>
      </geometry>
      <material name="">
        <color rgba="1.0 1.0 1.0 1.0"/>
      </material>
    </visual>
    <collision>
      <origin rpy="0 0 0" xyz="0 0 0"/>
      <geometry>
        <mesh filename="package://youbot_description/meshes/youbot_gripper/right_finger_link.STL"/>
      </geometry>
    </collision>
  </link>
  <joint name="gripper_right_finger_joint" type="fixed">
    <origin rpy="3.14159265358979 0 0" xyz="-0.0154362314517573 0.0263 -0.00390000000000003"/>
    <parent link="gripper_right_finger_fastener_link"/>
    <child link="gripper_right_finger_link"/>
    <axis xyz="0 0 0"/>
  </joint>
  <link name="gripper_camera_holder_link">
    <inertial>
      <origin rpy="0 0 0" xyz="-0.0154558187135768 0.0264554443238969 0.00610502534126566"/>
      <mass value="0.0575401627450105"/>
      <inertia ixx="1.88760755233664E-05" ixy="6.42179161095357E-08" ixz="6.70844267074005E-09" iyy="4.24323271397149E-05" iyz="-4.2719184355183E-06" izz="5.78252549958773E-05"/>
    </inertial>
    <visual>
      <origin rpy="0 0 0" xyz="0 0 0"/>
      <geometry>
        <mesh filename="package://youbot_description/meshes/youbot_gripper/camera_holder_link.STL"/>
      </geometry>
      <material name="">
        <color rgba="0.0 0.0 0.0 1.0"/>
      </material>
    </visual>
    <collision>
      <origin rpy="0 0 0" xyz="0 0 0"/>
      <geometry>
        <mesh filename="package://youbot_description/meshes/youbot_gripper/camera_holder_link.STL"/>
      </geometry>
    </collision>
  </link>
  <joint name="gripper_camera_holder_joint" type="fixed">
    <origin rpy="0 0 -3.14033747664133" xyz="-0.0309812074459294 0.0006459809840905 0.005"/>
    <parent link="gripper_base_holder_link"/>
    <child link="gripper_camera_holder_link"/>
    <axis xyz="0 0 0"/>
  </joint>
  <transmission name="gripper_right_finger_fastener_trans">
    <type>transmission_interface/SimpleTransmission</type>
    <actuator name="gripper_right_finger_fastener_motor">
      <hardwareInterface>hardware_interface/PositionJointInterface</hardwareInterface>
      <mechanicalReduction>1</mechanicalReduction>
    </actuator>
    <joint name="gripper_right_finger_fastener_joint">
      <hardwareInterface>hardware_interface/PositionJointInterface</hardwareInterface>
    </joint>
  </transmission>
  <transmission name="gripper_left_finger_fastener_trans">
    <type>transmission_interface/SimpleTransmission</type>
    <actuator name="gripper_left_finger_fastener_motor">
      <hardwareInterface>hardware_interface/PositionJointInterface</hardwareInterface>
      <mechanicalReduction>1</mechanicalReduction>
    </actuator>
    <joint name="gripper_left_finger_fastener_joint">
      <hardwareInterface>hardware_interface/PositionJointInterface</hardwareInterface>
    </joint>
  </transmission>
  <gazebo reference="gripper_base_holder_link">
    <material>Gazebo/Orange</material>
    <turnGravityOff>true</turnGravityOff>
    <selfCollide>true</selfCollide>
  </gazebo>
  <gazebo reference="gripper_left_finger_fastener_link">
    <material>Gazebo/Orange</material>
    <turnGravityOff>true</turnGravityOff>
    <selfCollide>true</selfCollide>
  </gazebo>
  <gazebo reference="gripper_right_finger_fastener_link">
    <material>Gazebo/Orange</material>
    <turnGravityOff>true</turnGravityOff>
    <selfCollide>true</selfCollide>
  </gazebo>
  <gazebo reference="gripper_servo_left_link">
    <material>Gazebo/Black</material>
  </gazebo>
  <gazebo reference="gripper_servo_right_link">
    <material>Gazebo/Black</material>
  </gazebo>
  <gazebo reference="gripper_camera_holder_link">
    <material>Gazebo/Black</material>
  </gazebo>
  
1
	
	
  <!-- joint between base_link and arm_0_link -->
  <joint name="arm_2_joint_0" type="fixed">
    <origin rpy="0 0 3.1415" xyz="-0.123 0 0.046"/>
    <parent link="base_link"/>
    <child link="arm_2_link_0"/>
  </joint>
  <link name="arm_2_link_0">
    <inertial>
      <!--<origin xyz="0.023 0 0.006" rpy="0 0 0"/>-->
      <origin rpy="0 0 0" xyz="0 0 0"/>
      <mass value="0.845"/>
      <inertia ixx="0.01" ixy="0" ixz="0" iyy="0.01" iyz="0" izz="0.01"/>
    </inertial>
    <visual>
      <origin rpy="0 0 0" xyz="0 0 0"/>
      <geometry>
        <mesh filename="package://youbot_description/meshes/youbot_arm/arm0.dae"/>
      </geometry>
      <material name="youBot/DarkGrey"/>
    </visual>
    <collision>
      <!--<origin xyz="0.023 0 0.006" rpy="0 0 0"/>-->
      <origin rpy="0 0 0" xyz="0 0 0"/>
      <geometry>
        <mesh filename="package://youbot_description/meshes/youbot_arm/arm0_convex.dae"/>
        <!--<cylinder length="0.078" radius="0.093"/>-->
      </geometry>
    </collision>
  </link>
  <!-- joint between arm_0_link and arm_1_link -->
  <joint name="arm_2_joint_1" type="revolute">
    <origin rpy="0 0 2.9670597283903604" xyz="0.024 0 0.096"/>
    <parent link="arm_2_link_0"/>
    <child link="arm_2_link_1"/>
    <axis xyz="0 0 -1"/>
    <!--<calibration rising="${arm_1_ref}" falling="${arm_1_ref}"/>-->
    <dynamics damping="1" friction="0.5"/>
    <!-- damping - N*s/m, N*s*m/rad -->
    <!-- friction - N, N*m -->
    <limit effort="9.5" lower="0" upper="5.899212871740834" velocity="1.5707963267948966"/>
    <!--effort - N, N*m-->
    <!--velocity - m/s, rad/s-->
    <!--safety_controller k_position="20" k_velocity="${9.5/M_PI / 2.0}" soft_lower_limit="${threshold}" soft_upper_limit="${joint_1_limit_soft}" /-->
    <!--k_position N/m, N/rad-->
    <!--k_velocity N*s/m, N*s*m/rad-->
    <!--for details: http://www.ros.org/wiki/pr2_controller_manager/safety_limits-->
  </joint>
  <link name="arm_2_link_1">
    <inertial>
      <mass value="2.412"/>
      <origin rpy="0 0 0" xyz="0.01489 0.00213 0.00213"/>
      <inertia ixx="0.003863" ixy="-0.000979" ixz="0.000000" iyy="0.006196" iyz="0.000000" izz="0.006369"/>
    </inertial>
    <visual>
      <origin rpy="0 0 0" xyz="0 0 0"/>
      <geometry>
        <mesh filename="package://youbot_description/meshes/youbot_arm/arm1.dae"/>
      </geometry>
      <material name="youBot/Orange"/>
    </visual>
    <collision>
      <!--<origin xyz="0 0 -0.003" rpy="0 0 0" />-->
      <origin rpy="0 0 0" xyz="0 0 0"/>
      <geometry>
        <mesh filename="package://youbot_description/meshes/youbot_arm/arm1_convex.dae"/>
        <!--<cylinder length="0.102" radius="0.080"/>-->
      </geometry>
    </collision>
  </link>
  <!-- joint between arm_1_link and arm_2_link -->
  <joint name="arm_2_joint_2" type="revolute">
    <origin rpy="0 -1.1344640137963142 0" xyz="0.033 0 0.019"/>
    <parent link="arm_2_link_1"/>
    <child link="arm_2_link_2"/>
    <axis xyz="0 1 0"/>
    <!--<calibration rising="${arm_2_ref}" falling="${arm_2_ref}"/>-->
    <dynamics damping="1" friction="0.5"/>
    <limit effort="9.5" lower="0" upper="2.705260340591211" velocity="1.5707963267948966"/>
    <!--safety_controller k_position="20" k_velocity="${2*9.5/M_PI}" soft_lower_limit="${threshold}" soft_upper_limit="${joint_2_limit_soft}" /-->
  </joint>
  <link name="arm_2_link_2">
    <inertial>
      <mass value="1.155"/>
      <origin rpy="0 0 0" xyz="0.10453 0.0017 -0.00297"/>
      <inertia ixx="0.000823" ixy="0.000000" ixz="-0.000000" iyy="0.004447" iyz="0.000000" izz="0.004439"/>
    </inertial>
    <visual>
      <origin rpy="0 0 0" xyz="0 -0.032 0.078"/>
      <geometry>
        <mesh filename="package://youbot_description/meshes/youbot_arm/arm2.dae"/>
      </geometry>
    </visual>
    <collision>
      <!--<origin xyz="0.001 -0.041 0.074" rpy="0 0 0" />-->
      <origin rpy="0 0 0" xyz="0 -0.032 0.078"/>
      <geometry>
        <mesh filename="package://youbot_description/meshes/youbot_arm/arm2_convex.dae"/>
        <!--<box size="0.074 0.082 0.222"/>-->
      </geometry>
    </collision>
  </link>
  <!-- joint between arm_2_link and arm_3_link -->
  <!--<joint name="${name}_joint_3" type="revolute">
			<origin xyz="0.000 0.000 0.155" rpy="0 ${146 * M_PI / 180} 0"/>
			<parent link="${name}_link_2"/>
			<child link="${name}_link_3"/>
			<axis xyz="0 1 0"/>
			<dynamics damping="1" friction="1" />
			<limit effort="${6}" velocity="${M_PI / 2.0}" lower="-${joint_3_limit}" upper="0"/>
      <safety_controller k_position="20" k_velocity="50" soft_lower_limit="-${joint_3_limit_soft}" soft_upper_limit="${threshold}" />
		</joint>-->
  <joint name="arm_2_joint_3" type="revolute">
    <origin rpy="0 2.548180707911721 0" xyz="0.000 0.000 0.155"/>
    <parent link="arm_2_link_2"/>
    <child link="arm_2_link_3"/>
    <axis xyz="0 1 0"/>
    <dynamics damping="1" friction="0.5"/>
    <limit effort="6.0" lower="-5.183627878423159" upper="0" velocity="1.5707963267948966"/>
    <!--safety_controller k_position="20" k_velocity="50" soft_lower_limit="-${joint_3_limit_soft}" soft_upper_limit="-${threshold}" /-->
  </joint>
  <link name="arm_2_link_3">
    <inertial>
      <mass value="0.934"/>
      <origin rpy="0 0 0" xyz="0.0001 0.09670000000000001 0.021070000000000002"/>
      <inertia ixx="0.002459" ixy="0.000000" ixz="0.000000" iyy="0.002571" iyz="-0.000000" izz="0.000535"/>
    </inertial>
    <visual>
      <origin rpy="0 0 0" xyz="0.000 0.028 0.079"/>
      <geometry>
        <mesh filename="package://youbot_description/meshes/youbot_arm/arm3.dae"/>
      </geometry>
      <material name="youBot/Orange"/>
    </visual>
    <collision>
      <!--<origin xyz="0.000 0.025 0.067" rpy="0 0 0" />-->
      <origin rpy="0 0 0" xyz="0.000 0.028 0.079"/>
      <geometry>
        <mesh filename="package://youbot_description/meshes/youbot_arm/arm3_convex.dae"/>
        <!--<box size="0.064 0.054 0.192"/>-->
      </geometry>
    </collision>
  </link>
  <!-- joint between arm_3_link and arm_4_link -->
  <joint name="arm_2_joint_4" type="revolute">
    <origin rpy="0 -1.7889624832941877 0" xyz="0.000 0.000 0.135"/>
    <parent link="arm_2_link_3"/>
    <child link="arm_2_link_4"/>
    <axis xyz="0 1 0"/>
    <!--<calibration rising="${arm_4_ref}" falling="${arm_4_ref}"/>-->
    <dynamics damping="1" friction="0.5"/>
    <limit effort="2.0" lower="0" upper="3.5779249665883754" velocity="1.5707963267948966"/>
    <!--safety_controller k_position="20" k_velocity="100" soft_lower_limit="0" soft_upper_limit="${joint_4_limit_soft}" /-->
  </joint>
  <link name="arm_2_link_4">
    <inertial>
      <mass value="0.877"/>
      <origin rpy="0 0 0" xyz="0.00011 0.05103 -0.023190000000000002"/>
      <inertia ixx="0.000869" ixy="0.000000" ixz="-0.000000" iyy="0.001173" iyz="-0.000231" izz="0.001091"/>
    </inertial>
    <visual>
      <origin rpy="0 0 0" xyz="0 -0.010 0.029"/>
      <geometry>
        <mesh filename="package://youbot_description/meshes/youbot_arm/arm4.dae"/>
      </geometry>
      <material name="youBot/Orange"/>
    </visual>
    <collision>
      <!--<origin xyz="0 0 0.026" rpy="0 0 0" />-->
      <origin rpy="0 0 0" xyz="0 -0.010 0.029"/>
      <geometry>
        <mesh filename="package://youbot_description/meshes/youbot_arm/arm4_convex.dae"/>
        <!--<box size="0.058 0.100 0.118"/>-->
      </geometry>
    </collision>
  </link>
  <!-- joint between arm_4_link and arm_5_link -->
  <joint name="arm_2_joint_5" type="revolute">
    <origin rpy="0 0 2.9234264970905017" xyz="-0.002 0 0.130"/>
    <parent link="arm_2_link_4"/>
    <child link="arm_2_link_5"/>
    <axis xyz="0 0 -1"/>
    <!--<calibration rising="${arm_5_ref}" falling="${arm_5_ref}"/>-->
    <dynamics damping="0.5" friction="0.5"/>
    <limit effort="1.0" lower="0" upper="5.8468529941810035" velocity="1.5707963267948966"/>
    <!--safety_controller k_position="20" k_velocity="100" soft_lower_limit="0" soft_upper_limit="${joint_5_limit_soft}" /-->
  </joint>
  <link name="arm_2_link_5">
    <inertial>
      <mass value="0.251"/>
      <origin rpy="0 0 0" xyz="0.0 0.00115 -0.016829999999999998"/>
      <inertia ixx="0.000280" ixy="0.000000" ixz="0.000000" iyy="0.000339" iyz="0.000000" izz="0.000119"/>
    </inertial>
    <visual>
      <origin rpy="0 0 0" xyz="0.003 0 -0.034"/>
      <geometry>
        <mesh filename="package://youbot_description/meshes/youbot_arm/arm5.dae"/>
      </geometry>
      <material name="youBot/DarkGrey"/>
    </visual>
    <collision>
      <origin rpy="0 0 0" xyz="0.003 0 -0.034"/>
      <geometry>
        <mesh filename="package://youbot_description/meshes/youbot_arm/arm5_convex.dae"/>
        <!--<box size="0.054 0.096 0.030"/>-->
      </geometry>
    </collision>
  </link>
  <gazebo reference="arm_2_link_0">
    <turnGravityOff>false</turnGravityOff>
  </gazebo>
  <gazebo reference="arm_2_link_1">
    <turnGravityOff>false</turnGravityOff>
  </gazebo>
  <gazebo reference="arm_2_link_2">
    <turnGravityOff>false</turnGravityOff>
  </gazebo>
  <gazebo reference="arm_2_link_3">
    <turnGravityOff>false</turnGravityOff>
  </gazebo>
  <gazebo reference="arm_2_link_4">
    <turnGravityOff>false</turnGravityOff>
  </gazebo>
  <gazebo reference="arm_2_link_5">
    <turnGravityOff>false</turnGravityOff>
  </gazebo>
  <transmission name="arm_2_trans_1">
    <type>transmission_interface/SimpleTransmission</type>
    <actuator name="arm_2_motor_1">
      <hardwareInterface>hardware_interface/EffortJointInterface</hardwareInterface>
      <mechanicalReduction>1</mechanicalReduction>
    </actuator>
    <joint name="arm_2_joint_1">
      <hardwareInterface>hardware_interface/EffortJointInterface</hardwareInterface>
    </joint>
  </transmission>
  <transmission name="arm_2_trans_2">
    <type>transmission_interface/SimpleTransmission</type>
    <actuator name="arm_2_motor_2">
      <hardwareInterface>hardware_interface/EffortJointInterface</hardwareInterface>
      <mechanicalReduction>1</mechanicalReduction>
    </actuator>
    <joint name="arm_2_joint_2">
      <hardwareInterface>hardware_interface/EffortJointInterface</hardwareInterface>
    </joint>
  </transmission>
  <transmission name="arm_2_trans_3">
    <type>transmission_interface/SimpleTransmission</type>
    <actuator name="arm_2_motor_3">
      <hardwareInterface>hardware_interface/EffortJointInterface</hardwareInterface>
      <mechanicalReduction>1</mechanicalReduction>
    </actuator>
    <joint name="arm_2_joint_3">
      <hardwareInterface>hardware_interface/EffortJointInterface</hardwareInterface>
    </joint>
  </transmission>
  <transmission name="arm_2_trans_4">
    <type>transmission_interface/SimpleTransmission</type>
    <actuator name="arm_2_motor_4">
      <hardwareInterface>hardware_interface/EffortJointInterface</hardwareInterface>
      <mechanicalReduction>1</mechanicalReduction>
    </actuator>
    <joint name="arm_2_joint_4">
      <hardwareInterface>hardware_interface/EffortJointInterface</hardwareInterface>
    </joint>
  </transmission>
  <transmission name="arm_2_trans_5">
    <type>transmission_interface/SimpleTransmission</type>
    <actuator name="arm_2_motor_5">
      <hardwareInterface>hardware_interface/EffortJointInterface</hardwareInterface>
      <mechanicalReduction>1</mechanicalReduction>
    </actuator>
    <joint name="arm_2_joint_5">
      <hardwareInterface>hardware_interface/EffortJointInterface</hardwareInterface>
    </joint>
  </transmission>
  <!-- <xacro:new_gripper_urdf name="gripper_2" parent="arm_2_link_5">
    <origin xyz="-0.00031 -0.01549 -0.017" rpy="0 0 -1.5708" />
  </xacro:new_gripper_urdf> -->
  <link name="youbot/camera_foot_link">
    <inertial>
      <mass value="0.05"/>
      <origin rpy="0 0 0" xyz="0 0 0"/>
      <inertia ixx="0.0001" ixy="0" ixz="0" iyy="0.0001" iyz="0" izz="0.0001"/>
    </inertial>
    <visual>
      <origin rpy="1.5707963267948966 0 1.5707963267948966" xyz="0.01 0 0"/>
      <geometry>
        <mesh filename="package://youbot_description/meshes/sensors/asus_xtion_pro_live_base.dae" scale="0.0004 0.0007 0.001"/>
      </geometry>
      <material name="Black"/>
    </visual>
    <collision>
      <origin rpy="1.5707963267948966 0 1.5707963267948966" xyz="0.01 0 0"/>
      <geometry>
        <mesh filename="package://youbot_description/meshes/sensors/asus_xtion_pro_live_base.dae" scale="0.0004 0.0007 0.001"/>
      </geometry>
    </collision>
  </link>
  <joint name="youbot/camera_foot_joint" type="fixed">
    <origin rpy="0 -1.60 3.14" xyz="0.02 0 -0.04"/>
    <parent link="arm_2_link_5"/>
    <child link="youbot/camera_foot_link"/>
  </joint>
  <link name="youbot/camera_tilt_link">
    <inertial>
      <mass value="0.01"/>
      <origin rpy="0 0 0" xyz="0 0 0"/>
      <inertia ixx="0.0001" ixy="0" ixz="0" iyy="0.0001" iyz="0" izz="0.0001"/>
    </inertial>
    <visual>
      <origin rpy="0 0 0" xyz="0 0 0.0075"/>
      <geometry>
        <cylinder length="0.025" radius="0.005"/>
      </geometry>
      <material name="Black"/>
    </visual>
    <collision>
      <origin rpy="0 0 0" xyz="0 0 0.0075"/>
      <geometry>
        <cylinder length="0.025" radius="0.005"/>
      </geometry>
      <material name="Black"/>
    </collision>
  </link>
  <joint name="asus_xtion_tilt_joint" type="fixed">
    <parent link="youbot/camera_foot_link"/>
    <child link="youbot/camera_tilt_link"/>
    <!--<axis xyz="0 1 0"/>-->
    <origin rpy="0 0.0 0" xyz="0 0 0.0075"/>
    <!--<limit effort="100" lower="-0.541052068" upper="0.541052068" velocity="1.0"/>-->
  </joint>
  <link name="youbot/camera_camera">
    <inertial>
      <mass value="0.1"/>
      <origin rpy="0 0 0" xyz="0 0 0"/>
      <inertia ixx="0.0001" ixy="0" ixz="0" iyy="0.0001" iyz="0" izz="0.0001"/>
    </inertial>
    <visual>
      <origin rpy="1.5707963267948966 0 1.5707963267948966" xyz="0.02 -0.03 0"/>
      <geometry>
        <mesh filename="package://youbot_description/meshes/sensors/asus_xtion_pro_live_camera.dae" scale="0.001 0.001 0.001"/>
      </geometry>
      <material name="Black"/>
    </visual>
    <collision>
      <origin rpy="1.5707963267948966 0 1.5707963267948966" xyz="0.02 -0.03 0"/>
      <geometry>
        <mesh filename="package://youbot_description/meshes/sensors/asus_xtion_pro_live_camera.dae" scale="0.001 0.001 0.001"/>
      </geometry>
    </collision>
  </link>
  <joint name="youbot/camera_camera_joint" type="fixed">
    <origin rpy="0 0 0" xyz="0 0.03 0.03"/>
    <parent link="youbot/camera_tilt_link"/>
    <child link="youbot/camera_camera"/>
  </joint>
  <link name="youbot/camera_depth_frame">
    <inertial>
      <mass value="0.01"/>
      <origin xyz="0 0 0"/>
      <inertia ixx="0.1" ixy="0" ixz="0" iyy="0.1" iyz="0" izz="0.1"/>
    </inertial>
  </link>
  <joint name="youbot/camera_depth_joint" type="fixed">
    <parent link="youbot/camera_camera"/>
    <child link="youbot/camera_depth_frame"/>
    <origin rpy="0 0 0" xyz="0.03 0.015000000000000003 0"/>
  </joint>
  <link name="youbot/camera_depth_optical_frame">
    <inertial>
      <mass value="0.01"/>
      <origin xyz="0 0 0"/>
      <inertia ixx="0.1" ixy="0" ixz="0" iyy="0.1" iyz="0" izz="0.1"/>
    </inertial>
  </link>
  <joint name="youbot/camera_depth_optical_joint" type="fixed">
    <parent link="youbot/camera_camera"/>
    <child link="youbot/camera_depth_optical_frame"/>
    <origin rpy="-1.5707963267948966 0 -1.5707963267948966" xyz="0.03 0.015000000000000003 0"/>
  </joint>
  <link name="youbot/camera_rgb_frame">
    <inertial>
      <mass value="0.01"/>
      <origin xyz="0 0 0"/>
      <inertia ixx="0.1" ixy="0" ixz="0" iyy="0.1" iyz="0" izz="0.1"/>
    </inertial>
  </link>
  <joint name="youbot/camera_rgb_joint" type="fixed">
    <parent link="youbot/camera_camera"/>
    <child link="youbot/camera_rgb_frame"/>
    <origin rpy="0 0 0" xyz="0.03 -0.0049999999999999975 0"/>
  </joint>
  <link name="youbot/camera_rgb_optical_frame">
    <inertial>
      <mass value="0.01"/>
      <origin xyz="0 0 0"/>
      <inertia ixx="0.1" ixy="0" ixz="0" iyy="0.1" iyz="0" izz="0.1"/>
    </inertial>
  </link>
  <joint name="youbot/camera_rgb_optical_joint" type="fixed">
    <parent link="youbot/camera_camera"/>
    <child link="youbot/camera_rgb_optical_frame"/>
    <origin rpy="-1.5707963267948966 0 -1.5707963267948966" xyz="0.03 -0.0049999999999999975 0"/>
  </joint>
  <link name="youbot/camera_laser_frame">
    <inertial>
      <mass value="0.01"/>
      <origin xyz="0 0 0"/>
      <inertia ixx="0.1" ixy="0" ixz="0" iyy="0.1" iyz="0" izz="0.1"/>
    </inertial>
  </link>
  <joint name="youbot/camera_laser_joint" type="fixed">
    <parent link="youbot/camera_camera"/>
    <child link="youbot/camera_laser_frame"/>
    <origin rpy="0 0 0" xyz="0.03 -0.05499999999999999 0"/>
  </joint>
  <link name="youbot/camera_laser_optical_frame">
    <inertial>
      <mass value="0.01"/>
      <origin xyz="0 0 0"/>
      <inertia ixx="0.1" ixy="0" ixz="0" iyy="0.1" iyz="0" izz="0.1"/>
    </inertial>
  </link>
  <joint name="youbot/camera_laser_optical_joint" type="fixed">
    <parent link="youbot/camera_camera"/>
    <child link="youbot/camera_laser_optical_frame"/>
    <origin rpy="1.5707963267948966 0 -1.5707963267948966" xyz="0.03 -0.05499999999999999 0"/>
  </joint>
  <gazebo reference="youbot/camera_camera">
    <sensor name="youbot/camera_depth_frame_sensor" type="depth">
      <always_on>true</always_on>
      <update_rate>20.0</update_rate>
      <camera>
        <horizontal_fov>0.9948376736367678</horizontal_fov>
        <image>
          <format>R8G8B8</format>
          <width>640</width>
          <height>480</height>
        </image>
        <clip>
          <near>0.1</near>
          <far>5</far>
        </clip>
      </camera>
      <plugin filename="libgazebo_ros_openni_kinect.so" name="youbot/camera_depth_frame_controller">
        <baseline>0.2</baseline>
        <alwaysOn>true</alwaysOn>
        <updateRate>20.0</updateRate>
        <cameraName>youbot/camera_depth</cameraName>
        <imageTopicName>/youbot/camera/ir/image_raw</imageTopicName>
        <cameraInfoTopicName>/youbot/camera/ir/camera_info</cameraInfoTopicName>
        <depthImageTopicName>/youbot/camera/depth/image_raw</depthImageTopicName>
        <depthImageCameraInfoTopicName>/youbot/camera/depth/camera_info</depthImageCameraInfoTopicName>
        <pointCloudTopicName>/youbot/camera/depth/points</pointCloudTopicName>
        <frameName>youbot/camera_depth_optical_frame</frameName>
        <pointCloudCutoff>0.5</pointCloudCutoff>
        <distortionK1>0.00000001</distortionK1>
        <distortionK2>0.00000001</distortionK2>
        <distortionK3>0.00000001</distortionK3>
        <distortionT1>0.00000001</distortionT1>
        <distortionT2>0.00000001</distortionT2>
        <CxPrime>0</CxPrime>
        <Cx>0</Cx>
        <Cy>0</Cy>
        <focalLength>0</focalLength>
        <hackBaseline>0</hackBaseline>
      </plugin>
    </sensor>
    <sensor name="youbot/camera_rgb_frame_sensor" type="depth">
      <always_on>true</always_on>
      <update_rate>20.0</update_rate>
      <camera>
        <horizontal_fov>0.9948376736367678</horizontal_fov>
        <image>
          <format>R8G8B8</format>
          <width>640</width>
          <height>480</height>
        </image>
        <clip>
          <near>0.1</near>
          <far>5</far>
        </clip>
      </camera>
      <plugin filename="libgazebo_ros_openni_kinect.so" name="youbot/camera_rgb_frame_controller">
        <baseline>0.2</baseline>
        <alwaysOn>true</alwaysOn>
        <updateRate>20.0</updateRate>
        <cameraName>youbot/camera_rgb</cameraName>
        <imageTopicName>/youbot/camera/rgb/image_raw</imageTopicName>
        <cameraInfoTopicName>/youbot/camera/rgb/camera_info</cameraInfoTopicName>
        <depthImageTopicName>/youbot/camera/depth_registered/image_raw</depthImageTopicName>
        <depthImageCameraInfoTopicName>/youbot/camera/depth_registered/camera_info</depthImageCameraInfoTopicName>
        <pointCloudTopicName>/youbot/camera/depth_registered/points</pointCloudTopicName>
        <frameName>youbot/camera_rgb_optical_frame</frameName>
        <pointCloudCutoff>0.5</pointCloudCutoff>
        <distortionK1>0.00000001</distortionK1>
        <distortionK2>0.00000001</distortionK2>
        <distortionK3>0.00000001</distortionK3>
        <distortionT1>0.00000001</distortionT1>
        <distortionT2>0.00000001</distortionT2>
        <CxPrime>0</CxPrime>
        <Cx>0</Cx>
        <Cy>0</Cy>
        <focalLength>0</focalLength>
        <hackBaseline>0</hackBaseline>
      </plugin>
    </sensor>
  </gazebo>
  <!-- 3D camera on tower -->
  <!-- <xacro:sensor_d435 name="camera" parent="arm_2_link_5">
    <origin xyz="0.02 0 -0.04" rpy="0 -1.60 3.14" />
  </xacro:sensor_d435> -->
  <joint name="base_laser_front_hokuyo_urg04_laser_joint" type="fixed">
    <axis xyz="0 1 0"/>
    <origin rpy="0 0 0" xyz="0.3 0 -0.03"/>
    <parent link="base_link"/>
    <child link="base_laser_front_link"/>
  </joint>
  <link name="base_laser_front_link" type="laser">
    <inertial>
      <mass value="0.16"/>
      <origin rpy="0 0 0" xyz="0 0 0"/>
      <inertia ixx="0.1" ixy="0" ixz="0" iyy="0.1" iyz="0" izz="0.1"/>
    </inertial>
    <visual>
      <origin rpy="0 0 0" xyz="0 0 0"/>
      <geometry>
        <mesh filename="package://youbot_description/meshes/sensors/hokuyo.dae"/>
      </geometry>
    </visual>
    <collision>
      <origin rpy="0 0 0" xyz="0 0 0"/>
      <geometry>
        <mesh filename="package://youbot_description/meshes/sensors/hokuyo_convex.dae"/>
      </geometry>
    </collision>
  </link>
  <gazebo reference="base_laser_front_link">
    <sensor name="base_laser_front" type="ray">
      <always_on>true</always_on>
      <update_rate>10</update_rate>
      <pose>0 0 0 0 0 0</pose>
      <visualize>false</visualize>
      <ray>
        <scan>
          <horizontal>
            <samples>150</samples>
            <resolution>1.0</resolution>
            <min_angle>-1.57</min_angle>
            <max_angle>1.57</max_angle>
          </horizontal>
        </scan>
        <range>
          <min>0.05</min>
          <max>5.6</max>
          <resolution>0.36</resolution>
        </range>
      </ray>
      <plugin filename="libgazebo_ros_laser.so" name="gazebo_ros_base_laser_front_controller">
        <gaussianNoise>0.005</gaussianNoise>
        <alwaysOn>true</alwaysOn>
        <updateRate>10</updateRate>
        <topicName>youbot/scan</topicName>
        <frameName>/base_laser_front_link</frameName>
      </plugin>
    </sensor>
  </gazebo>
</robot>

